<?xml version="1.0"?>
<robot name="bot2">

  <gazebo>
	<plugin name="gazebo_ros_control" filename="libgazebo_ros_control.so">
	<robotNamespace>bot2</robotNamespace>
	<robotSimType>gazebo_ros_control/DefaultRobotHWSim</robotSimType>
    	<legacyModeNS>true</legacyModeNS>
	</plugin>
  </gazebo>

  <gazebo>
    <plugin name="bot2_controller" filename="libgazebo_ros_diff_drive.so">
      <commandTopic>cmd_vel</commandTopic>
      <odometryTopic>odom</odometryTopic>
      <odometryFrame>odom</odometryFrame>
      <odometrySource>world</odometrySource>
      <publishOdomTF>true</publishOdomTF>
      <robotBaseFrame>base_footprint</robotBaseFrame>
      <publishWheelTF>false</publishWheelTF>
      <publishTf>true</publishTf>
      <publishWheelJointState>true</publishWheelJointState>
      <legacyMode>false</legacyMode>
      <updateRate>30</updateRate>
      <leftJoint>left_tyre_joint</leftJoint>
      <rightJoint>right_tyre_joint</rightJoint>
      <wheelSeparation>0.646</wheelSeparation>
      <wheelDiameter>0.270</wheelDiameter>
      <wheelAcceleration>1.2</wheelAcceleration>
      <wheelTorque>10</wheelTorque>
      <rosDebugLevel>na</rosDebugLevel>
    </plugin>
  </gazebo>

  <gazebo reference="laser_link">
    <material>Gazebo/Grey</material>
    <sensor type="ray" name="lds_lfcd_sensor">
      <pose>0 0 0 0 0 0</pose>
      <visualize>false</visualize>
      <update_rate>10</update_rate>
      <ray>
        <scan>
          <horizontal>
            <samples>360</samples>
            <resolution>1</resolution>
            <min_angle>0.0</min_angle>
            <max_angle>6.28319</max_angle>
          </horizontal>
        </scan>
        <range>
          <min>0.120</min>
          <max>5</max>
          <resolution>0.015</resolution>
        </range>
        <noise>
          <type>gaussian</type>
          <mean>0.0</mean>
          <stddev>0.01</stddev>
        </noise>
      </ray>
      <plugin name="gazebo_ros_lds_lfcd_controller" filename="libgazebo_ros_laser.so">
        <topicName>/scan</topicName>
        <frameName>laser_link</frameName>
      </plugin>
    </sensor>
  </gazebo>


  <link name="base_footprint"/>

  <joint name="base_joint" type="fixed">
    <parent link="base_footprint"/>
    <child link="base_link"/>
    <origin xyz="0.0 0.0 0.010" rpy="0 0 0"/>
  </joint>

  <joint name="counter_weight_joint" type="fixed">
    <parent link="base_link"/>
    <child link="counter_weight_link"/>
    <origin xyz="0.5 0.0 0.1" rpy="0 0 0"/>
  </joint>

  <link name="counter_weight_link">
    <visual>
      <origin rpy="0 0 0" xyz="0 0 0"/>
      <geometry>
	<box size= "0.1 0.1 0.1"/>
      </geometry>
    </visual>
    
    <inertial>
      <origin xyz="0 0 0" rpy="0 0 0"/>
      <mass value="1" />
      <inertia ixx="0.00166666666667" ixy="0.0" ixz="0.0" iyy="0.00166666666667" iyz="0.0" izz="0.00166666666667"/>
    </inertial>

    <collision>
      <origin xyz="0 0 0" rpy="0 0 0"/>
      <geometry>
      <box size="0.02 0.02 0.02"/>
      </geometry>
    </collision>

  </link>

  <link name="base_link">
    <visual>
      <origin rpy="0 0 0" xyz="0 0 0"/>
      <geometry>
	<mesh filename="package://igvc_bot/models/meshes/bot2.dae"/>
      </geometry>
    </visual>

    <inertial>
      <origin xyz="0 0 0" rpy="0 0 0"/>
      <mass value="8" />
      <inertia ixx="0.222416666667" ixy="0.0" ixz="0.0" iyy="1" iyz="0.0"
izz="0.732002666667"/>
    </inertial>

    <collision>
      <origin xyz="0 0 0" rpy="0 0 0"/>
      <geometry>
      <mesh filename="package://igvc_bot/models/meshes/bot2.dae"/>
      </geometry>
    </collision>
  </link>

  <gazebo reference="base_link">
    <kp>1000.0</kp>
    <kd>10.0</kd>
    <mu1>10.0</mu1>
    <mu2>10.0</mu2>
    <material>Gazebo/White</material>
  </gazebo>

  <link name="left_tyre_link">
    <visual>
    <origin rpy="0 0 0" xyz="0 0 0" />
      <geometry>
	<mesh filename="package://igvc_bot/models/meshes/tyre1.dae"/>
      </geometry>
    </visual>

    <inertial>
      <origin xyz="0 0 0" rpy="0 0 0"/>
      <mass value="0.2" />
      <inertia ixx="0.00098" ixy="0.0" ixz="0.0" iyy="0.00098" iyz="0.0"
izz="0.00169"/>
    </inertial>

    <collision>
      <origin xyz="0 0 0" rpy="1.57 0 0"/>
      <geometry>
      <cylinder radius="0.135" length ="0.09"/>
      </geometry>
    </collision>

  </link>

  <gazebo reference="left_tyre_link">
    <mu1>0.4</mu1>
    <mu2>0.4</mu2>
    <kp>100000.0</kp>
    <kd>10.0</kd>
    <minDepth>0.001</minDepth>
    <fdir1>1 0 0</fdir1>
    <material>Gazebo/FlatBlack</material>
  </gazebo>

  <joint name="left_tyre_joint" type="continuous">
    <parent link="base_link"/>
    <child link="left_tyre_link"/>
    <origin xyz="0.0 0.323 0" rpy="0 0 0"/>
    <limit  effort="2" velocity="5"/>
    <axis xyz="0 1 0"/>	
  </joint>

  <link name="right_tyre_link">
    <visual>
    <origin rpy="0 0 0" xyz="0 0 0" />
      <geometry>
	<mesh filename="package://igvc_bot/models/meshes/tyre1.dae"/>
      </geometry>
    </visual>

    <inertial>
      <origin xyz="0 0 0" rpy="0 0 0"/>
      <mass value="0.2" />
      <inertia ixx="0.00098" ixy="0.0" ixz="0.0" iyy="0.00098" iyz="0.0"
izz="0.00169"/>
    </inertial>

    <collision>
      <origin xyz="0 0 0" rpy="1.57 0 0"/>
      <geometry>
      <cylinder radius="0.135" length ="0.09"/>
      </geometry>
    </collision>

  </link>

  <gazebo reference="right_tyre_link">
    <mu1>0.4</mu1>
    <mu2>0.4</mu2>
    <kp>100000.0</kp>
    <kd>10.0</kd>
    <minDepth>0.001</minDepth>
    <fdir1>1 0 0</fdir1>
    <material>Gazebo/FlatBlack</material>    
  </gazebo>

  <joint name="right_tyre_joint" type="continuous">
    <parent link="base_link"/>
    <child link="right_tyre_link"/>
    <origin xyz="0.0 -0.323 0" rpy="0 0 0"/>
    <limit  effort="2" velocity="5"/>
    <axis xyz="0 1 0"/>
  </joint>

  <link name="caster_link">
    <visual>
    <origin rpy="0 0 0" xyz="0 0 0" />
      <geometry>
	<mesh filename="package://igvc_bot/models/meshes/castors1.dae"/>
      </geometry>
    </visual>

    <inertial>
      <origin xyz="0 0 0" rpy="0 0 0"/>
      <mass value="0.05" />
      <inertia ixx="6.57541666667e-05" ixy="0.0" ixz="0.0" iyy="6.57541666667e-05" iyz="0.0" izz="6.25e-05"/>
    </inertial>

    <collision>
      <origin xyz="0 0 -0.055" rpy="1.57 0 0"/>
      <geometry>
      <cylinder radius ="0.05" length="0.091"/>
      </geometry>
    </collision>
  </link>

  <gazebo reference="caster_link">
    <kp>10000.0</kp>
    <kd>10000.0</kd>
    <mu1>0.1</mu1>
    <mu2>0.1</mu2>
    <material>Gazebo/Grey</material>
  </gazebo>

  <joint name="caster_joint" type="fixed">
    <parent link="base_link"/>
    <child link="caster_link"/>
    <origin xyz="0.48 0 0.019" rpy="0 0 0"/>
    <limit  effort="2" velocity="5"/>
  </joint>

<link name="laser_link">
    <visual>
    <origin rpy="0 0 0" xyz="0 0 0" />
      <geometry>
	<mesh filename="package://igvc_bot/models/meshes/sick-lms1xx.dae"/>
      </geometry>
    </visual>

    <inertial>
      <origin xyz="0 0 0" rpy="0 0 0"/>
      <mass value="0.05" />
      <inertia ixx="6.57541666667e-05" ixy="0.0" ixz="0.0" iyy="6.57541666667e-05" iyz="0.0" izz="6.25e-05"/>
    </inertial>

    <collision>
      <origin xyz="0 0 0" rpy="0 0 0"/>
      <geometry>
      <cylinder radius ="0.09" length="0.147"/>
      </geometry>
    </collision>
  </link>

  <joint name="laser_link_joint" type="fixed">
    <parent link="base_link"/>
    <child link="laser_link"/>
    <origin xyz="0.76 0 0.39" rpy="0 0 0"/>
    <limit  effort="2" velocity="5"/>
  </joint>

  <gazebo reference="laser_link">
    <kp>1000.0</kp>
    <kd>1000.0</kd>
    <mu1>1.0</mu1>
    <mu2>1.0</mu2>
    <material>Gazebo/Grey</material>
  </gazebo>

</robot>
